2024-04-30 06:30:21,396 Could not connect to Redis instance: Connection closed by server. Retrying in 1 seconds...
Exception in thread Thread-1:
Traceback (most recent call last):
  File "/home/frappe/.pyenv/versions/3.11.6/lib/python3.11/threading.py", line 1045, in _bootstrap_inner
    self.run()
  File "/workspace/frappe-bench/env/lib/python3.11/site-packages/redis/client.py", line 1164, in run
    pubsub.get_message(ignore_subscribe_messages=True, timeout=sleep_time)
  File "/workspace/frappe-bench/env/lib/python3.11/site-packages/redis/client.py", line 1026, in get_message
    response = self.parse_response(block=(timeout is None), timeout=timeout)
               ^^^^^^^^^^^^^^^^^^^^^^^^^^^^^^^^^^^^^^^^^^^^^^^^^^^^^^^^^^^^^
  File "/workspace/frappe-bench/env/lib/python3.11/site-packages/redis/client.py", line 837, in parse_response
    response = self._execute(conn, try_read)
               ^^^^^^^^^^^^^^^^^^^^^^^^^^^^^
  File "/workspace/frappe-bench/env/lib/python3.11/site-packages/redis/client.py", line 813, in _execute
    return conn.retry.call_with_retry(
           ^^^^^^^^^^^^^^^^^^^^^^^^^^^
  File "/workspace/frappe-bench/env/lib/python3.11/site-packages/redis/retry.py", line 49, in call_with_retry
    fail(error)
  File "/workspace/frappe-bench/env/lib/python3.11/site-packages/redis/client.py", line 815, in <lambda>
    lambda error: self._disconnect_raise_connect(conn, error),
                  ^^^^^^^^^^^^^^^^^^^^^^^^^^^^^^^^^^^^^^^^^^^
  File "/workspace/frappe-bench/env/lib/python3.11/site-packages/redis/client.py", line 802, in _disconnect_raise_connect
    raise error
  File "/workspace/frappe-bench/env/lib/python3.11/site-packages/redis/retry.py", line 46, in call_with_retry
    return do()
           ^^^^
  File "/workspace/frappe-bench/env/lib/python3.11/site-packages/redis/client.py", line 814, in <lambda>
    lambda: command(*args, **kwargs),
            ^^^^^^^^^^^^^^^^^^^^^^^^
  File "/workspace/frappe-bench/env/lib/python3.11/site-packages/redis/client.py", line 831, in try_read
    if not conn.can_read(timeout=timeout):
           ^^^^^^^^^^^^^^^^^^^^^^^^^^^^^^
  File "/workspace/frappe-bench/env/lib/python3.11/site-packages/redis/connection.py", line 490, in can_read
    return self._parser.can_read(timeout)
           ^^^^^^^^^^^^^^^^^^^^^^^^^^^^^^
  File "/workspace/frappe-bench/env/lib/python3.11/site-packages/redis/_parsers/hiredis.py", line 75, in can_read
    return self.read_from_socket(timeout=timeout, raise_on_timeout=False)
           ^^^^^^^^^^^^^^^^^^^^^^^^^^^^^^^^^^^^^^^^^^^^^^^^^^^^^^^^^^^^^^
  File "/workspace/frappe-bench/env/lib/python3.11/site-packages/redis/_parsers/hiredis.py", line 86, in read_from_socket
    raise ConnectionError(SERVER_CLOSED_CONNECTION_ERROR)
redis.exceptions.ConnectionError: Connection closed by server.
2024-04-30 06:30:22,500 Could not connect to Redis instance: Error -2 connecting to redis-queue:6379. Name or service not known. Retrying in 2 seconds...
2024-04-30 06:30:24,509 Could not connect to Redis instance: Error -2 connecting to redis-queue:6379. Name or service not known. Retrying in 4 seconds...
2024-04-30 06:30:28,571 Could not connect to Redis instance: Error -2 connecting to redis-queue:6379. Name or service not known. Retrying in 8 seconds...
2024-04-30 09:47:35,953 Could not connect to Redis instance: Connection closed by server. Retrying in 1 seconds...
Exception in thread Thread-1:
Traceback (most recent call last):
  File "/home/frappe/.pyenv/versions/3.11.6/lib/python3.11/threading.py", line 1045, in _bootstrap_inner
    self.run()
  File "/workspace/frappe-bench/env/lib/python3.11/site-packages/redis/client.py", line 1164, in run
    pubsub.get_message(ignore_subscribe_messages=True, timeout=sleep_time)
  File "/workspace/frappe-bench/env/lib/python3.11/site-packages/redis/client.py", line 1026, in get_message
    response = self.parse_response(block=(timeout is None), timeout=timeout)
               ^^^^^^^^^^^^^^^^^^^^^^^^^^^^^^^^^^^^^^^^^^^^^^^^^^^^^^^^^^^^^
  File "/workspace/frappe-bench/env/lib/python3.11/site-packages/redis/client.py", line 837, in parse_response
    response = self._execute(conn, try_read)
               ^^^^^^^^^^^^^^^^^^^^^^^^^^^^^
  File "/workspace/frappe-bench/env/lib/python3.11/site-packages/redis/client.py", line 813, in _execute
    return conn.retry.call_with_retry(
           ^^^^^^^^^^^^^^^^^^^^^^^^^^^
  File "/workspace/frappe-bench/env/lib/python3.11/site-packages/redis/retry.py", line 49, in call_with_retry
    fail(error)
  File "/workspace/frappe-bench/env/lib/python3.11/site-packages/redis/client.py", line 815, in <lambda>
    lambda error: self._disconnect_raise_connect(conn, error),
                  ^^^^^^^^^^^^^^^^^^^^^^^^^^^^^^^^^^^^^^^^^^^
  File "/workspace/frappe-bench/env/lib/python3.11/site-packages/redis/client.py", line 802, in _disconnect_raise_connect
    raise error
  File "/workspace/frappe-bench/env/lib/python3.11/site-packages/redis/retry.py", line 46, in call_with_retry
    return do()
           ^^^^
  File "/workspace/frappe-bench/env/lib/python3.11/site-packages/redis/client.py", line 814, in <lambda>
    lambda: command(*args, **kwargs),
            ^^^^^^^^^^^^^^^^^^^^^^^^
  File "/workspace/frappe-bench/env/lib/python3.11/site-packages/redis/client.py", line 831, in try_read
    if not conn.can_read(timeout=timeout):
           ^^^^^^^^^^^^^^^^^^^^^^^^^^^^^^
  File "/workspace/frappe-bench/env/lib/python3.11/site-packages/redis/connection.py", line 490, in can_read
    return self._parser.can_read(timeout)
           ^^^^^^^^^^^^^^^^^^^^^^^^^^^^^^
  File "/workspace/frappe-bench/env/lib/python3.11/site-packages/redis/_parsers/hiredis.py", line 75, in can_read
    return self.read_from_socket(timeout=timeout, raise_on_timeout=False)
           ^^^^^^^^^^^^^^^^^^^^^^^^^^^^^^^^^^^^^^^^^^^^^^^^^^^^^^^^^^^^^^
  File "/workspace/frappe-bench/env/lib/python3.11/site-packages/redis/_parsers/hiredis.py", line 86, in read_from_socket
    raise ConnectionError(SERVER_CLOSED_CONNECTION_ERROR)
redis.exceptions.ConnectionError: Connection closed by server.
2024-04-30 09:47:37,093 Could not connect to Redis instance: Error -2 connecting to redis-queue:6379. Name or service not known. Retrying in 2 seconds...
2024-04-30 09:47:39,106 Could not connect to Redis instance: Error -2 connecting to redis-queue:6379. Name or service not known. Retrying in 4 seconds...
2024-04-30 09:47:43,117 Could not connect to Redis instance: Error -2 connecting to redis-queue:6379. Name or service not known. Retrying in 8 seconds...
